Warning: no access to tty (Bad file descriptor).
Thus no job control in this shell.
./boot.bash: line 7: module: command not found
Error: prefix already exists: /home/s1510756/py27
discarding /work/opt/anaconda/py35/bin from PATH
prepending /home/s1510756/py27/bin to PATH
Requirement already satisfied: enum34==1.1.2 in ./py27/lib/python2.7/site-packages (from -r /home/s1510756/hpcc/requirements.txt (line 1))
Requirement already satisfied: matplotlib==1.5.1 in ./py27/lib/python2.7/site-packages (from -r /home/s1510756/hpcc/requirements.txt (line 2))
Requirement already satisfied: numpy==1.10.4 in ./py27/lib/python2.7/site-packages (from -r /home/s1510756/hpcc/requirements.txt (line 3))
Requirement already satisfied: scipy==0.17.0 in ./py27/lib/python2.7/site-packages (from -r /home/s1510756/hpcc/requirements.txt (line 4))
Requirement already satisfied: scikit-learn==0.17.1 in ./py27/lib/python2.7/site-packages (from -r /home/s1510756/hpcc/requirements.txt (line 5))
Requirement already satisfied: unidiff==0.5.2 in ./py27/lib/python2.7/site-packages (from -r /home/s1510756/hpcc/requirements.txt (line 6))
Requirement already satisfied: psycopg2==2.6.1 in ./py27/lib/python2.7/site-packages (from -r /home/s1510756/hpcc/requirements.txt (line 7))
Requirement already satisfied: python-dateutil in ./py27/lib/python2.7/site-packages (from matplotlib==1.5.1->-r /home/s1510756/hpcc/requirements.txt (line 2))
Requirement already satisfied: pytz in ./py27/lib/python2.7/site-packages (from matplotlib==1.5.1->-r /home/s1510756/hpcc/requirements.txt (line 2))
Requirement already satisfied: cycler in ./py27/lib/python2.7/site-packages (from matplotlib==1.5.1->-r /home/s1510756/hpcc/requirements.txt (line 2))
Requirement already satisfied: pyparsing!=2.0.4,>=1.5.6 in ./py27/lib/python2.7/site-packages (from matplotlib==1.5.1->-r /home/s1510756/hpcc/requirements.txt (line 2))
Requirement already satisfied: six>=1.5 in ./py27/lib/python2.7/site-packages (from python-dateutil->matplotlib==1.5.1->-r /home/s1510756/hpcc/requirements.txt (line 2))
No protocol specified
No protocol specified
Started loading data
Data loaded #840
Start extracting lines...
Completed extracting lines including #0 invalid patches.
{0: 0.3614590230646415}
Traceback (most recent call last):
  File "/home/s1510756/hpcc/vcc-combine.py", line 126, in <module>
    plt.clf()
  File "/home/s1510756/py27/lib/python2.7/site-packages/matplotlib/pyplot.py", line 665, in clf
    gcf().clf()
  File "/home/s1510756/py27/lib/python2.7/site-packages/matplotlib/pyplot.py", line 578, in gcf
    return figure()
  File "/home/s1510756/py27/lib/python2.7/site-packages/matplotlib/pyplot.py", line 527, in figure
    **kwargs)
  File "/home/s1510756/py27/lib/python2.7/site-packages/matplotlib/backends/backend_tkagg.py", line 84, in new_figure_manager
    return new_figure_manager_given_figure(num, figure)
  File "/home/s1510756/py27/lib/python2.7/site-packages/matplotlib/backends/backend_tkagg.py", line 92, in new_figure_manager_given_figure
    window = Tk.Tk()
  File "/home/s1510756/py27/lib/python2.7/lib-tk/Tkinter.py", line 1815, in __init__
    self.tk = _tkinter.create(screenName, baseName, className, interactive, wantobjects, useTk, sync, use)
_tkinter.TclError: couldn't connect to display ":0"
