Warning: no access to tty (Bad file descriptor).
Thus no job control in this shell.
Error: prefix already exists: /home/s1510756/py27
discarding /work/opt/anaconda/py35/bin from PATH
prepending /home/s1510756/py27/bin to PATH
Requirement already satisfied: enum34==1.1.2 in ./py27/lib/python2.7/site-packages (from -r /home/s1510756/hpcc/requirements.txt (line 1))
Requirement already satisfied: matplotlib==1.5.1 in ./py27/lib/python2.7/site-packages (from -r /home/s1510756/hpcc/requirements.txt (line 2))
Requirement already satisfied: numpy==1.10.4 in ./py27/lib/python2.7/site-packages (from -r /home/s1510756/hpcc/requirements.txt (line 3))
Requirement already satisfied: scipy==0.17.0 in ./py27/lib/python2.7/site-packages (from -r /home/s1510756/hpcc/requirements.txt (line 4))
Requirement already satisfied: scikit-learn==0.17.1 in ./py27/lib/python2.7/site-packages (from -r /home/s1510756/hpcc/requirements.txt (line 5))
Requirement already satisfied: unidiff==0.5.2 in ./py27/lib/python2.7/site-packages (from -r /home/s1510756/hpcc/requirements.txt (line 6))
Requirement already satisfied: psycopg2==2.6.1 in ./py27/lib/python2.7/site-packages (from -r /home/s1510756/hpcc/requirements.txt (line 7))
Requirement already satisfied: python-dateutil in ./py27/lib/python2.7/site-packages (from matplotlib==1.5.1->-r /home/s1510756/hpcc/requirements.txt (line 2))
Requirement already satisfied: pytz in ./py27/lib/python2.7/site-packages (from matplotlib==1.5.1->-r /home/s1510756/hpcc/requirements.txt (line 2))
Requirement already satisfied: cycler in ./py27/lib/python2.7/site-packages (from matplotlib==1.5.1->-r /home/s1510756/hpcc/requirements.txt (line 2))
Requirement already satisfied: pyparsing!=2.0.4,>=1.5.6 in ./py27/lib/python2.7/site-packages (from matplotlib==1.5.1->-r /home/s1510756/hpcc/requirements.txt (line 2))
Requirement already satisfied: six>=1.5 in ./py27/lib/python2.7/site-packages (from python-dateutil->matplotlib==1.5.1->-r /home/s1510756/hpcc/requirements.txt (line 2))
Started loading data
Data loaded #351409
Start extracting lines...
Completed extracting lines including #445 invalid patches.
Traceback (most recent call last):
  File "/home/s1510756/hpcc/vcc-combine.py", line 117, in <module>
    y_score = classifier.fit(X_train, y_train).decision_function(X_test)
  File "/home/s1510756/py27/lib/python2.7/site-packages/sklearn/svm/classes.py", line 213, in fit
    self.loss)
  File "/home/s1510756/py27/lib/python2.7/site-packages/sklearn/svm/base.py", line 887, in _fit_liblinear
    class_weight_ = compute_class_weight(class_weight, classes_, y)
  File "/home/s1510756/py27/lib/python2.7/site-packages/sklearn/utils/class_weight.py", line 45, in compute_class_weight
    if class_weight is None or len(class_weight) == 0:
TypeError: object of type 'int' has no len()
